<?xml version="1.0" ?>

<robot name="mobile_manipulator">

  <!-- #################### MiR #################### -->
  <!-- ############################################# -->
    <link name="MiR_footprint"/>

    <joint name="MiR__footprint_to_base_fixed_joint" type="fixed">
      <parent link="MiR_footprint"/>
      <child link="MiR_base_link"/>
      <origin rpy="0 0 0" xyz="0 0 0"/>
    </joint>

    <link name="MiR_base_link">
      <inertial>
        <mass value="58.0"/>
        <origin rpy="0 0 0" xyz="0.037646 0 0.20"/>
        <inertia ixx="2.0609325089599997" ixy="0.0" ixz="0.0" iyy="4.34999826" iyz="0.0" izz="5.54093111696"/>
      </inertial>
      <visual>
        <origin rpy="0 0 0" xyz="0.037646 0 0"/>
        <geometry>
          <mesh filename="package://mobile_manipulator/mesh/mir100/visual/mir_100_base.stl"/>
        </geometry>
        <material name="white">
          <color rgba="1 1 1 1"/>
        </material>
      </visual>
      <collision>
        <origin rpy="0 0 0" xyz="0.037646 0 0"/>
        <geometry>
          <mesh filename="package://mobile_manipulator/mesh/mir100/collision/mir_100_base.stl"/>
        </geometry>
      </collision>
    </link>

    <joint name="MiR__base_left_wheel_continous_joint" type="continuous">
      <origin rpy="0 0 0" xyz="0.0 0.222604 0.0625"/>
      <parent link="MiR_base_link"/>
      <child link="MiR_left_wheel_link"/>
      <axis xyz="0 1 0"/>
      <limit effort="100" velocity="20.0"/>
    </joint>

    <link name="MiR_left_wheel_link">
      <inertial>
        <mass value="1.0"/>
        <origin rpy="1.5707963267948966 0 0" xyz="0 0 0"/>
        <inertia ixx="0.001061895408575" ixy="0.0" ixz="0.0" iyy="0.001061895408575" iyz="0.0" izz="0.001953125"/>
      </inertial>
      <visual>
        <origin rpy="0 0 0" xyz="0 0 0"/>
        <geometry>
          <mesh filename="package://mobile_manipulator/mesh/mir100/visual/wheel.stl"/>
        </geometry>
        <material name="dark_grey">
          <color rgba="0.3 0.3 0.3 1"/>
        </material>
      </visual>
      <collision>
        <origin rpy="0 0 0" xyz="0 0 0"/>
        <geometry>
          <mesh filename="package://mobile_manipulator/mesh/mir100/visual/wheel.stl"/>
        </geometry>
      </collision>
    </link>

    <joint name="MiR__base_right_wheel_continous_joint" type="continuous">
      <origin rpy="0 0 0" xyz="0.0 -0.222604 0.0625"/>
      <parent link="MiR_base_link"/>
      <child link="MiR_right_wheel_link"/>
      <axis xyz="0 1 0"/>
      <limit effort="100" velocity="20.0"/>
    </joint>

    <link name="MiR_right_wheel_link">
      <inertial>
        <mass value="1.0"/>
        <origin rpy="1.5707963267948966 0 0" xyz="0 0 0"/>
        <inertia ixx="0.001061895408575" ixy="0.0" ixz="0.0" iyy="0.001061895408575" iyz="0.0" izz="0.001953125"/>
      </inertial>
      <visual>
        <origin rpy="0 0 0" xyz="0 0 0"/>
        <geometry>
          <mesh filename="package://mobile_manipulator/mesh/mir100/visual/wheel.stl"/>
        </geometry>
        <material name="dark_grey">
          <color rgba="0.3 0.3 0.3 1"/>
        </material>
      </visual>
      <collision>
        <origin rpy="0 0 0" xyz="0 0 0"/>
        <geometry>
          <mesh filename="package://mobile_manipulator/mesh/mir100/visual/wheel.stl"/>
        </geometry>
      </collision>
    </link>

    <!-- caster hub -->
    <joint name="MiR__base_fl_caster_rotation_continous_joint" type="continuous">
      <origin rpy="0 0 0" xyz="0.341346 0.203 0.1565"/>
      <parent link="MiR_base_link"/>
      <child link="MiR_fl_caster_rotation_link"/>
      <axis xyz="0 0 1"/>
      <dynamics damping="0.01" friction="0.0"/>
    </joint>

    <link name="MiR_fl_caster_rotation_link">
      <inertial>
        <!-- <origin xyz="0 0 -0.042500000044" rpy="${0.5 * pi} ${24 * deg_to_rad} ${1.5 * pi}" /> -->
        <origin rpy="0.41887903200000004 0 1.5707963267948966 " xyz="0 0 -0.042500000044"/>
        <mass value="0.3097539019"/>
        <inertia ixx="0.0005844517978" ixy="0" ixz="0" iyy="0.00052872551237" iyz="0" izz="0.00017923555074"/>
      </inertial>
      <visual>
        <origin rpy="0 0 0" xyz="0 0 0"/>
        <geometry>
          <mesh filename="package://mobile_manipulator/mesh/mir100/visual/caster_wheel_base.stl"/>
        </geometry>
        <material name="silver">
          <color rgba="0.79 0.82 0.93 1"/>
        </material>
      </visual>
      <collision>
        <origin rpy="0 0 0" xyz="0 0 0"/>
        <geometry>
          <mesh filename="package://mobile_manipulator/mesh/mir100/collision/caster_wheel_base.stl"/>
        </geometry>
      </collision>
    </link>

    <!-- caster wheel -->
    <joint name="MiR__base_fl_caster_wheel_continous_joint" type="continuous">
      <origin rpy="0 0 0" xyz="-0.0382 0 -0.094"/>
      <parent link="MiR_fl_caster_rotation_link"/>
      <child link="MiR_fl_caster_wheel_link"/>
      <axis xyz="0 1 0"/>
    </joint>

    <link name="MiR_fl_caster_wheel_link">
      <inertial>
        <mass value="1.0"/>
        <origin rpy="1.5707963267948966 0 0" xyz="0 0 0"/>
        <inertia ixx="0.001061895408575" ixy="0.0" ixz="0.0" iyy="0.001061895408575" iyz="0.0" izz="0.001953125"/>
      </inertial>
      <visual>
        <origin rpy="0 0 0" xyz="0 0 0"/>
        <geometry>
          <mesh filename="package://mobile_manipulator/mesh/mir100/visual/wheel.stl"/>
        </geometry>
        <material name="dark_grey">
          <color rgba="0.3 0.3 0.3 1"/>
        </material>
      </visual>
      <collision>
        <origin rpy="0 0 0" xyz="0 0 0"/>
        <geometry>
          <mesh filename="package://mobile_manipulator/mesh/mir100/visual/wheel.stl"/>
        </geometry>
      </collision>
    </link>

    <!-- caster hub -->
    <joint name="MiR__base_fr_caster_rotation_continous_joint" type="continuous">
      <origin rpy="0 0 0" xyz="0.341346 -0.203 0.1565"/>
      <parent link="MiR_base_link"/>
      <child link="MiR_fr_caster_rotation_link"/>
      <axis xyz="0 0 1"/>
      <dynamics damping="0.01" friction="0.0"/>
    </joint>

    <link name="MiR_fr_caster_rotation_link">
      <inertial>
        <!-- <origin xyz="0 0 -0.042500000044" rpy="${0.5 * pi} ${24 * deg_to_rad} ${1.5 * pi}" /> -->
        <origin rpy="0.41887903200000004 0 1.5707963267948966 " xyz="0 0 -0.042500000044"/>
        <mass value="0.3097539019"/>
        <inertia ixx="0.0005844517978" ixy="0" ixz="0" iyy="0.00052872551237" iyz="0" izz="0.00017923555074"/>
      </inertial>
      <visual>
        <origin rpy="0 0 0" xyz="0 0 0"/>
        <geometry>
          <mesh filename="package://mobile_manipulator/mesh/mir100/visual/caster_wheel_base.stl"/>
        </geometry>
        <material name="silver">
          <color rgba="0.79 0.82 0.93 1"/>
        </material>
      </visual>
      <collision>
        <origin rpy="0 0 0" xyz="0 0 0"/>
        <geometry>
          <mesh filename="package://mobile_manipulator/mesh/mir100/collision/caster_wheel_base.stl"/>
        </geometry>
      </collision>
    </link>

    <!-- caster wheel -->
    <joint name="MiR__base_fr_caster_wheel_continous_joint" type="continuous">
      <origin rpy="0 0 0" xyz="-0.0382 0 -0.094"/>
      <parent link="MiR_fr_caster_rotation_link"/>
      <child link="MiR_fr_caster_wheel_link"/>
      <axis xyz="0 1 0"/>
    </joint>

    <link name="MiR_fr_caster_wheel_link">
      <inertial>
        <mass value="1.0"/>
        <origin rpy="1.5707963267948966 0 0" xyz="0 0 0"/>
        <inertia ixx="0.001061895408575" ixy="0.0" ixz="0.0" iyy="0.001061895408575" iyz="0.0" izz="0.001953125"/>
      </inertial>
      <visual>
        <origin rpy="0 0 0" xyz="0 0 0"/>
        <geometry>
          <mesh filename="package://mobile_manipulator/mesh/mir100/visual/wheel.stl"/>
        </geometry>
        <material name="dark_grey">
          <color rgba="0.3 0.3 0.3 1"/>
        </material>
      </visual>
      <collision>
        <origin rpy="0 0 0" xyz="0 0 0"/>
        <geometry>
          <mesh filename="package://mobile_manipulator/mesh/mir100/visual/wheel.stl"/>
        </geometry>
      </collision>
    </link>

    <!-- caster hub -->
    <joint name="MiR__base_bl_caster_rotation_continous_joint" type="continuous">
      <origin rpy="0 0 0" xyz="-0.270154 0.203 0.1565"/>
      <parent link="MiR_base_link"/>
      <child link="MiR_bl_caster_rotation_link"/>
      <axis xyz="0 0 1"/>
      <dynamics damping="0.01" friction="0.0"/>
    </joint>

    <link name="MiR_bl_caster_rotation_link">
      <inertial>
        <!-- <origin xyz="0 0 -0.042500000044" rpy="${0.5 * pi} ${24 * deg_to_rad} ${1.5 * pi}" /> -->
        <origin rpy="0.41887903200000004 0 1.5707963267948966 " xyz="0 0 -0.042500000044"/>
        <mass value="0.3097539019"/>
        <inertia ixx="0.0005844517978" ixy="0" ixz="0" iyy="0.00052872551237" iyz="0" izz="0.00017923555074"/>
      </inertial>
      <visual>
        <origin rpy="0 0 0" xyz="0 0 0"/>
        <geometry>
          <mesh filename="package://mobile_manipulator/mesh/mir100/visual/caster_wheel_base.stl"/>
        </geometry>
        <material name="silver">
          <color rgba="0.79 0.82 0.93 1"/>
        </material>
      </visual>
      <collision>
        <origin rpy="0 0 0" xyz="0 0 0"/>
        <geometry>
          <mesh filename="package://mobile_manipulator/mesh/mir100/collision/caster_wheel_base.stl"/>
        </geometry>
      </collision>
    </link>

    <!-- caster wheel -->
    <joint name="MiR__base_bl_caster_wheel_continous_joint" type="continuous">
      <origin rpy="0 0 0" xyz="-0.0382 0 -0.094"/>
      <parent link="MiR_bl_caster_rotation_link"/>
      <child link="MiR_bl_caster_wheel_link"/>
      <axis xyz="0 1 0"/>
    </joint>

    <link name="MiR_bl_caster_wheel_link">
      <inertial>
        <mass value="1.0"/>
        <origin rpy="1.5707963267948966 0 0" xyz="0 0 0"/>
        <inertia ixx="0.001061895408575" ixy="0.0" ixz="0.0" iyy="0.001061895408575" iyz="0.0" izz="0.001953125"/>
      </inertial>
      <visual>
        <origin rpy="0 0 0" xyz="0 0 0"/>
        <geometry>
          <mesh filename="package://mobile_manipulator/mesh/mir100/visual/wheel.stl"/>
        </geometry>
        <material name="dark_grey">
          <color rgba="0.3 0.3 0.3 1"/>
        </material>
      </visual>
      <collision>
        <origin rpy="0 0 0" xyz="0 0 0"/>
        <geometry>
          <mesh filename="package://mobile_manipulator/mesh/mir100/visual/wheel.stl"/>
        </geometry>
      </collision>
    </link>

    <!-- caster hub -->
    <joint name="MiR__base_br_caster_rotation_continous_joint" type="continuous">
      <origin rpy="0 0 0" xyz="-0.270154 -0.203 0.1565"/>
      <parent link="MiR_base_link"/>
      <child link="MiR_br_caster_rotation_link"/>
      <axis xyz="0 0 1"/>
      <dynamics damping="0.01" friction="0.0"/>
    </joint>

    <link name="MiR_br_caster_rotation_link">
      <inertial>
        <!-- <origin xyz="0 0 -0.042500000044" rpy="${0.5 * pi} ${24 * deg_to_rad} ${1.5 * pi}" /> -->
        <origin rpy="0.41887903200000004 0 1.5707963267948966 " xyz="0 0 -0.042500000044"/>
        <mass value="0.3097539019"/>
        <inertia ixx="0.0005844517978" ixy="0" ixz="0" iyy="0.00052872551237" iyz="0" izz="0.00017923555074"/>
      </inertial>
      <visual>
        <origin rpy="0 0 0" xyz="0 0 0"/>
        <geometry>
          <mesh filename="package://mobile_manipulator/mesh/mir100/visual/caster_wheel_base.stl"/>
        </geometry>
        <material name="silver">
          <color rgba="0.79 0.82 0.93 1"/>
        </material>
      </visual>
      <collision>
        <origin rpy="0 0 0" xyz="0 0 0"/>
        <geometry>
          <mesh filename="package://mobile_manipulator/mesh/mir100/collision/caster_wheel_base.stl"/>
        </geometry>
      </collision>
    </link>

    <!-- caster wheel -->
    <joint name="MiR__base_br_caster_wheel_continous_joint" type="continuous">
      <origin rpy="0 0 0" xyz="-0.0382 0 -0.094"/>
      <parent link="MiR_br_caster_rotation_link"/>
      <child link="MiR_br_caster_wheel_link"/>
      <axis xyz="0 1 0"/>
    </joint>

    <link name="MiR_br_caster_wheel_link">
      <inertial>
        <mass value="1.0"/>
        <origin rpy="1.5707963267948966 0 0" xyz="0 0 0"/>
        <inertia ixx="0.001061895408575" ixy="0.0" ixz="0.0" iyy="0.001061895408575" iyz="0.0" izz="0.001953125"/>
      </inertial>
      <visual>
        <origin rpy="0 0 0" xyz="0 0 0"/>
        <geometry>
          <mesh filename="package://mobile_manipulator/mesh/mir100/visual/wheel.stl"/>
        </geometry>
        <material name="dark_grey">
          <color rgba="0.3 0.3 0.3 1"/>
        </material>
      </visual>
      <collision>
        <origin rpy="0 0 0" xyz="0 0 0"/>
        <geometry>
          <mesh filename="package://mobile_manipulator/mesh/mir100/visual/wheel.stl"/>
        </geometry>
      </collision>
    </link>

    <joint name="MiR__base_to_surface_fixed_joint" type="fixed">
      <origin rpy="0 0 0" xyz="0.037646 0 0.352"/>
      <parent link="MiR_base_link"/>
      <child link="MiR_surface"/>
      <axis xyz="0 0 1"/>
    </joint>

    <link name="MiR_surface"/>

    <!-- IMU -->
    <joint name="MiR__base_to_imu_fixed_joint" type="fixed">
      <parent link="MiR_base_link"/>
      <child link="MiR_imu_link"/>
      <origin rpy="0 0 0" xyz="0.0 0.0 0.25"/>
      <!-- same as real MiR -->
    </joint>

    <link name="MiR_imu_link"/>

    <!-- Create an alias for imu_link. This is necessary because the real MiR's
            TF has imu_link, but the imu_data topic is published in the imu_frame
            frame. -->
    <joint name="MiR__imu_link_to_imu_frame_fixed_joint" type="fixed">
      <parent link="MiR_imu_link"/>
      <child link="MiR_imu_frame"/>
      <origin rpy="0 0 0" xyz="0 0 0"/>
    </joint>

    <link name="MiR_imu_frame"/>

  <!-- ############################################# -->
  <!-- #################### MiR #################### -->

  <!-- #################### UR10 ################### -->
  <!-- ############################################# -->
    <link name="UR10_base_link">
      <visual>
        <geometry>
          <mesh filename="package://mobile_manipulator/mesh/ur10/visual/base.dae"/>
        </geometry>
        <material name="LightGrey">
          <color rgba="0.7 0.7 0.7 1.0"/>
        </material>
      </visual>
      <collision>
        <geometry>
          <mesh filename="package://mobile_manipulator/mesh/ur10/collision/base.stl"/>
        </geometry>
      </collision>
      <inertial>
        <mass value="4.0"/>
        <origin rpy="0 0 0" xyz="0.0 0.0 0.0"/>
        <inertia ixx="0.0061063308908" ixy="0.0" ixz="0.0" iyy="0.0061063308908" iyz="0.0" izz="0.01125"/>
      </inertial>
    </link>

    <joint name="UR10__base_to_shoulder_pan_revolute_joint" type="revolute">
      <parent link="UR10_base_link"/>
      <child link="UR10_shoulder_pan_link"/>
      <origin rpy="0.0 0.0 0.0" xyz="0.0 0.0 0.1273"/>
      <axis xyz="0 0 1"/>
      <limit effort="330.0" lower="-3.141592653589793" upper="3.141592653589793" velocity="2.16"/>
      <dynamics damping="0.0" friction="0.0"/>
    </joint>

    <link name="UR10_shoulder_pan_link">
      <visual>
        <geometry>
          <mesh filename="package://mobile_manipulator/mesh/ur10/visual/shoulder.dae"/>
        </geometry>
        <material name="LightGrey">
          <color rgba="0.7 0.7 0.7 1.0"/>
        </material>
      </visual>
      <collision>
        <geometry>
          <mesh filename="package://mobile_manipulator/mesh/ur10/collision/shoulder.stl"/>
        </geometry>
      </collision>
      <inertial>
        <mass value="7.778"/>
        <origin rpy="0 0 0" xyz="0.0 0.0 0.0"/>
        <inertia ixx="0.03147431257693659" ixy="0.0" ixz="0.0" iyy="0.03147431257693659" iyz="0.0" izz="0.021875624999999996"/>
      </inertial>
    </link>

    <joint name="UR10__shoulder_pan_to_upper_arm_revolute_joint" type="revolute">
      <parent link="UR10_shoulder_pan_link"/>
      <child link="UR10_upper_arm_link"/>
      <origin rpy="0.0 0.0 0.0" xyz="0.0 0.220941 0.0"/>
      <axis xyz="0 1 0"/>
      <limit effort="330.0" lower="-3.141592653589793" upper="3.141592653589793" velocity="2.16"/>
      <dynamics damping="0.0" friction="0.0"/>
    </joint>

    <link name="UR10_upper_arm_link">
      <visual>
        <geometry>
          <mesh filename="package://mobile_manipulator/mesh/ur10/visual/upperarm.dae"/>
        </geometry>
        <material name="LightGrey">
          <color rgba="0.7 0.7 0.7 1.0"/>
        </material>
      </visual>
      <collision>
        <geometry>
          <mesh filename="package://mobile_manipulator/mesh/ur10/collision/upperarm.stl"/>
        </geometry>
      </collision>
      <inertial>
        <mass value="12.93"/>
        <origin rpy="0 0 0" xyz="0.0 -0.045 0.306"/>
        <inertia ixx="0.42175380379841093" ixy="0.0" ixz="0.0" iyy="0.42175380379841093" iyz="0.0" izz="0.03636562499999999"/>
      </inertial>
    </link>

    <joint name="UR10__upper_arm_to_fore_arm_revolute_joint" type="revolute">
      <parent link="UR10_upper_arm_link"/>
      <child link="UR10_fore_arm_link"/>
      <origin rpy="0.0 0.0 0.0" xyz="0.0 -0.1719 0.612"/>
      <axis xyz="0 1 0"/>
      <limit effort="150.0" lower="-3.141592653589793" upper="3.141592653589793" velocity="3.15"/>
      <dynamics damping="0.0" friction="0.0"/>
    </joint>

    <link name="UR10_fore_arm_link">
      <visual>
        <geometry>
          <mesh filename="package://mobile_manipulator/mesh/ur10/visual/forearm.dae"/>
        </geometry>
        <material name="LightGrey">
          <color rgba="0.7 0.7 0.7 1.0"/>
        </material>
      </visual>
      <collision>
        <geometry>
          <mesh filename="package://mobile_manipulator/mesh/ur10/collision/forearm.stl"/>
        </geometry>
      </collision>
      <inertial>
        <mass value="3.87"/>
        <origin rpy="0 0 0" xyz="0.0 0.0 0.28615"/>
        <inertia ixx="0.11106969409710458" ixy="0.0" ixz="0.0" iyy="0.11106969409710458" iyz="0.0" izz="0.010884375"/>
      </inertial>
    </link>

    <joint name="UR10__fore_arm_to_wrist_1_revolute_joint" type="revolute">
      <parent link="UR10_fore_arm_link"/>
      <child link="UR10_wrist_1_link"/>
      <origin rpy="0.0 0.0 0.0" xyz="0.0 0.0 0.5723"/>
      <axis xyz="0 1 0"/>
      <limit effort="54.0" lower="-3.141592653589793" upper="3.141592653589793" velocity="3.2"/>
      <dynamics damping="0.0" friction="0.0"/>
    </joint>

    <link name="UR10_wrist_1_link">
      <visual>
        <geometry>
          <mesh filename="package://mobile_manipulator/mesh/ur10/visual/wrist1.dae"/>
        </geometry>
        <material name="LightGrey">
          <color rgba="0.7 0.7 0.7 1.0"/>
        </material>
      </visual>
      <collision>
        <geometry>
          <mesh filename="package://mobile_manipulator/mesh/ur10/collision/wrist1.stl"/>
        </geometry>
      </collision>
      <inertial>
        <mass value="1.96"/>
        <origin rpy="0 0 0" xyz="0.0 0.1149 0.0"/>
        <inertia ixx="0.005108247956699999" ixy="0.0" ixz="0.0" iyy="0.005108247956699999" iyz="0.0" izz="0.005512499999999999"/>
      </inertial>
    </link>

    <joint name="UR10__wrist_1_to_wrist_2_revolute_joint" type="revolute">
      <parent link="UR10_wrist_1_link"/>
      <child link="UR10_wrist_2_link"/>
      <origin rpy="0.0 0.0 -1.5707963267948966" xyz="0.0 0.1149 0.0"/>
      <axis xyz="0 0 1"/>
      <limit effort="54.0" lower="-3.141592653589793" upper="3.141592653589793" velocity="3.2"/>
      <dynamics damping="0.0" friction="0.0"/>
    </joint>

    <link name="UR10_wrist_2_link">
      <visual>
        <geometry>
          <mesh filename="package://mobile_manipulator/mesh/ur10/visual/wrist2.dae"/>
        </geometry>
        <material name="LightGrey">
          <color rgba="0.7 0.7 0.7 1.0"/>
        </material>
      </visual>
      <collision>
        <geometry>
          <mesh filename="package://mobile_manipulator/mesh/ur10/collision/wrist2.stl"/>
        </geometry>
      </collision>
      <inertial>
        <mass value="1.96"/>
        <origin rpy="0 0 0" xyz="0.0 0.0 0.1157"/>
        <inertia ixx="0.005108247956699999" ixy="0.0" ixz="0.0" iyy="0.005108247956699999" iyz="0.0" izz="0.005512499999999999"/>
      </inertial>
    </link>

    <joint name="UR10__wrist_2_to_wrist_3_revolute_joint" type="revolute">
      <parent link="UR10_wrist_2_link"/>
      <child link="UR10_wrist_3_link"/>
      <origin rpy="0.0 0.0 0.0" xyz="0.0 0.0 0.1157"/>
      <axis xyz="0 1 0"/>
      <limit effort="54.0" lower="-3.141592653589793" upper="3.141592653589793" velocity="3.2"/>
      <dynamics damping="0.0" friction="0.0"/>
    </joint>

    <link name="UR10_wrist_3_link">
      <visual>
        <geometry>
          <mesh filename="package://mobile_manipulator/mesh/ur10/visual/wrist3.dae"/>
        </geometry>
        <material name="LightGrey">
          <color rgba="0.7 0.7 0.7 1.0"/>
        </material>
      </visual>
      <collision>
        <geometry>
          <mesh filename="package://mobile_manipulator/mesh/ur10/collision/wrist3.stl"/>
        </geometry>
      </collision>
      <inertial>
        <mass value="0.202"/>
        <origin rpy="1.5707963267948966 0 0" xyz="0.0 0.07695 0.0"/>
        <inertia ixx="0.00011792166116465" ixy="0.0" ixz="0.0" iyy="0.00011792166116465" iyz="0.0" izz="0.00020452500000000002"/>
      </inertial>
    </link>

    <joint name="UR10__wrist_3_to_end_effector_fixed_joint" type="fixed">
      <parent link="UR10_wrist_3_link"/>
      <child link="UR10_end_effector_link"/>
      <origin rpy="0.0 0.0 1.5707963267948966" xyz="0.0 0.0922 0.0"/>
    </joint>

    <link name="UR10_end_effector_link">
      <collision>
        <geometry>
          <box size="0.01 0.01 0.01"/>
        </geometry>
        <origin rpy="0 0 0" xyz="-0.01 0 0"/>
      </collision>
    </link>

  <!-- ############################################# -->
  <!-- #################### UR10 ################### -->

  <!-- ********************************** -->
  <!-- UR10 Arm connection to Mobile Base -->
    <joint name="UR10_base_to_MiR_base_fixed_joint" type="fixed">
      <origin rpy="0.0 0.0 0.0" xyz="0.15 0.0 0.352"/>
      <parent link="MiR_base_link"/>
      <child link="UR10_base_link"/>
    </joint>
  <!-- UR10 Arm connection to Mobile Base -->
  <!-- ********************************** -->

  <!-- #################### Barrett Hand #################### -->
  <!-- ###################################################### -->
    <link name="BH282_base_link">
      <inertial>
        <mass value="1.0"/>
        <origin xyz="0 0 0"/>
        <inertia ixx="1.0" ixy="0.0" ixz="0.0" iyy="1.0" iyz="0.0" izz="1.0"/>
      </inertial>
      <visual>
        <origin rpy="0 0 0" xyz="0 0 0"/>
        <geometry>
          <mesh filename="package://mobile_manipulator/mesh/barret/palm_282.dae"/>
        </geometry>
        <color rgba="0.75 0.75 0.75 1.0"/>
      </visual>
      <collision>
        <origin rpy="0 0 0 " xyz="0 0 0"/>
        <geometry>
          <mesh filename="package://mobile_manipulator/mesh/barret/palm_282.dae"/>
        </geometry>
        <contact_coefficients kd="1.0" kp="1000.0" mu="0"/>
      </collision>
    </link>

    <!-- Finger 1-->
    <link name="BH282_finger_11_link">
      <inertial>
        <mass value="0.1"/>
        <origin rpy="0 0 0" xyz="-0.046 0 0"/>
        <inertia ixx="0.01" ixy="0" ixz="0" iyy="0.01" iyz="0" izz="0.01"/>
      </inertial>
      <visual>
        <origin rpy="0 0 0" xyz="0 0 0"/>
        <geometry>
          <mesh filename="package://mobile_manipulator/mesh/barret/knuckle.dae"/>
        </geometry>
      </visual>
      <collision>
        <origin rpy="0 0 0" xyz="0 0 0"/>
        <geometry>
          <mesh filename="package://mobile_manipulator/mesh/barret/knuckle.dae"/>
        </geometry>
      </collision>
    </link>

    <joint name="BH282__base_to_finger_11_revolute_joint" type="revolute">
      <parent link="BH282_base_link"/>
      <child link="BH282_finger_11_link"/>
      <origin rpy="0 0 1.5708" xyz="-0.025 0 0.0252"/>
      <axis xyz="0 0 -1"/>
      <limit effort="30.0" lower="0" upper="3.141592653589793" velocity="2.0"/>
      <dynamics damping="100.0" friction="1.0"/>
    </joint>

    <link name="BH282_finger_12_link">
      <inertial>
        <mass value="0.1"/>
        <origin rpy="0 0 0" xyz="0 0 0"/>
        <inertia ixx="0.01" ixy="0" ixz="0" iyy="0.01" iyz="0" izz="0.01"/>
      </inertial>
      <visual>
        <origin rpy="0 0 0" xyz="0 0 0"/>
        <geometry>
          <mesh filename="package://mobile_manipulator/mesh/barret/finger.dae"/>
        </geometry>
      </visual>
      <collision>
        <origin rpy="0 0 0" xyz="0 0 0"/>
        <geometry>
          <mesh filename="package://mobile_manipulator/mesh/barret/finger.dae"/>
        </geometry>
        <contact_coefficients kd="1.0" kp="1000.0" mu="0"/>
      </collision>
    </link>

    <joint name="BH282__finger_11_to_finger_12_revolute_joint" type="revolute">
      <parent link="BH282_finger_11_link"/>
      <child link="BH282_finger_12_link"/>
      <origin rpy="1.5707963267948966 0 0" xyz="-0.05 0 0.0339"/>
      <axis xyz="0 0 -1"/>
      <limit effort="30.0" lower="0.0" upper="2.44" velocity="2.0"/>
      <dynamics damping="100.0" friction="1.0"/>
    </joint>

    <link name="BH282_finger_13_link">
      <inertial>
        <mass value="0.1"/>
        <origin rpy="0 0 0" xyz="0 0 0"/>
        <inertia ixx="0.01" ixy="0" ixz="0" iyy="0.01" iyz="0" izz="0.01"/>
      </inertial>
      <visual>
        <origin rpy="0 0 0" xyz="0 0 0"/>
        <geometry>
          <mesh filename="package://mobile_manipulator/mesh/barret/finger_tip.dae"/>
        </geometry>
      </visual>
      <collision>
        <origin rpy="0 0 0" xyz="0 0 0"/>
        <geometry>
          <mesh filename="package://mobile_manipulator/mesh/barret/finger_tip.dae"/>
        </geometry>
        <contact_coefficients kd="1.0" kp="1000.0" mu="0"/>
      </collision>
    </link>

    <joint name="BH282__finger_12_to_finger_13_revolute_joint" type="revolute">
      <parent link="BH282_finger_12_link"/>
      <child link="BH282_finger_13_link"/>
      <origin rpy="0 0 0" xyz="-0.069936 0.003 0"/>
      <axis xyz="0 0 -1"/>
      <limit effort="30.0" lower="0.0" upper="0.84" velocity="2.0"/>
      <dynamics damping="100.0" friction="1.0"/>
    </joint>

    <!-- Finger 2-->
    <link name="BH282_finger_21_link">
      <inertial>
        <mass value="0.1"/>
        <origin rpy="0 0 0" xyz="-0.046 0 0"/>
        <inertia ixx="0.01" ixy="0" ixz="0" iyy="0.01" iyz="0" izz="0.01"/>
      </inertial>
      <visual>
        <origin rpy="0 0 0" xyz="0 0 0"/>
        <geometry>
          <mesh filename="package://mobile_manipulator/mesh/barret/knuckle.dae"/>
        </geometry>
      </visual>
      <collision>
        <origin rpy="0 0 0" xyz="0 0 0"/>
        <geometry>
          <mesh filename="package://mobile_manipulator/mesh/barret/knuckle.dae"/>
        </geometry>
      </collision>
    </link>

    <joint name="BH282__base_to_finger_21_revolute_joint" type="revolute">
      <parent link="BH282_base_link"/>
      <child link="BH282_finger_21_link"/>
      <origin rpy="0 0 1.5707963267948966" xyz="0.025 0 0.0252"/>
      <axis xyz="0 0 1"/>
      <limit effort="30.0" lower="0" upper="3.141592653589793" velocity="2.0"/>
      <dynamics damping="100.0" friction="1.0"/>
    </joint>

    <link name="BH282_finger_22_link">
      <inertial>
        <mass value="0.1"/>
        <origin rpy="0 0 0" xyz="0 0 0"/>
        <inertia ixx="0.01" ixy="0" ixz="0" iyy="0.01" iyz="0" izz="0.01"/>
      </inertial>
      <visual>
        <origin rpy="0 0 0" xyz="0 0 0"/>
        <geometry>
          <mesh filename="package://mobile_manipulator/mesh/barret/finger.dae"/>
        </geometry>
      </visual>
      <collision>
        <origin rpy="0 0 0" xyz="0 0 0"/>
        <geometry>
          <mesh filename="package://mobile_manipulator/mesh/barret/finger.dae"/>
        </geometry>
        <contact_coefficients kd="1.0" kp="1000.0" mu="0"/>
      </collision>
    </link>

    <joint name="BH282__finger_21_to_finger_22_revolute_joint" type="revolute">
      <parent link="BH282_finger_21_link"/>
      <child link="BH282_finger_22_link"/>
      <origin rpy="1.5707963267948966 -8.8281E-17 0" xyz="-0.05 0 0.0339"/>
      <axis xyz="0 0 -1"/>
      <limit effort="30.0" lower="0.0" upper="2.44" velocity="2.0"/>
      <dynamics damping="100.0" friction="1.0"/>
    </joint>

    <link name="BH282_finger_23_link">
      <inertial>
        <mass value="0.1"/>
        <origin rpy="0 0 0" xyz="0 0 0"/>
        <inertia ixx="0.01" ixy="0" ixz="0" iyy="0.01" iyz="0" izz="0.01"/>
      </inertial>
      <visual>
        <origin rpy="0 0 0" xyz="0 0 0"/>
        <geometry>
          <mesh filename="package://mobile_manipulator/mesh/barret/finger_tip.dae"/>
        </geometry>
      </visual>
      <collision>
        <origin rpy="0 0 0" xyz="0 0 0"/>
        <geometry>
          <mesh filename="package://mobile_manipulator/mesh/barret/finger_tip.dae"/>
        </geometry>
        <contact_coefficients kd="1.0" kp="1000.0" mu="0"/>
      </collision>
    </link>

    <joint name="BH282__finger_22_to_finger_23_revolute_joint" type="revolute">
      <parent link="BH282_finger_22_link"/>
      <child link="BH282_finger_23_link"/>
      <origin rpy="0 0 0" xyz="-0.069936 0.003 0"/>
      <axis xyz="0 0 -1"/>
      <limit effort="30.0" lower="0.0" upper="0.84" velocity="2.0"/>
      <dynamics damping="100.0" friction="1.0"/>
    </joint>

    <!-- Finger 3-->
    <link name="BH282_finger_31_link">
      <inertial>
        <mass value="0.1"/>
        <origin rpy="0 0 0" xyz="-0.046 0 0"/>
        <inertia ixx="0.01" ixy="0" ixz="0" iyy="0.01" iyz="0" izz="0.01"/>
      </inertial>
      <visual>
        <origin rpy="0 0 0" xyz="-0.04 0 0"/>
        <geometry>
          <mesh filename="package://mobile_manipulator/mesh/barret/knuckle_fixed.dae"/>
        </geometry>
      </visual>
      <collision>
        <origin rpy="0 0 0" xyz="-0.04 0 0"/>
        <geometry>
          <mesh filename="package://mobile_manipulator/mesh/barret/knuckle_fixed.dae"/>
        </geometry>
        <contact_coefficients kd="1.0" kp="1000.0" mu="0"/>
      </collision>
    </link>

    <joint name="BH282__base_to_finger_31_fixed_joint" type="fixed">
      <parent link="BH282_base_link"/>
      <child link="BH282_finger_31_link"/>
      <origin rpy="0 0 -1.5707963267948966" xyz="0 0 0.0252"/>
    </joint>

    <link name="BH282_finger_32_link">
      <inertial>
        <mass value="0.1"/>
        <origin rpy="0 0 0" xyz="0 0 0"/>
        <inertia ixx="0.01" ixy="0" ixz="0" iyy="0.01" iyz="0" izz="0.01"/>
      </inertial>
      <visual>
        <origin rpy="0 0 0" xyz="0 0 0"/>
        <geometry>
          <mesh filename="package://mobile_manipulator/mesh/barret/finger.dae"/>
        </geometry>
      </visual>
      <collision>
        <origin rpy="0 0 0" xyz="0 0 0"/>
        <geometry>
          <mesh filename="package://mobile_manipulator/mesh/barret/finger.dae"/>
        </geometry>
        <contact_coefficients kd="1.0" kp="1000.0" mu="0"/>
      </collision>
    </link>

    <joint name="BH282__finger_31_to_finger_32_revolute_joint" type="revolute">
      <parent link="BH282_finger_31_link"/>
      <child link="BH282_finger_32_link"/>
      <origin rpy="1.5707963267948966 -8.8281E-17 0" xyz="-0.05 0 0.0339"/>
      <axis xyz="0 0 -1"/>
      <limit effort="30.0" lower="0.0" upper="2.44" velocity="2.0"/>
      <dynamics damping="100.0" friction="1.0"/>
    </joint>

    <link name="BH282_finger_33_link">
      <inertial>
        <mass value="0.1"/>
        <origin rpy="0 0 0" xyz="0 0 0"/>
        <inertia ixx="0.01" ixy="0" ixz="0" iyy="0.01" iyz="0" izz="0.01"/>
      </inertial>
      <visual>
        <origin rpy="0 0 0" xyz="0 0 0"/>
        <geometry>
          <mesh filename="package://mobile_manipulator/mesh/barret/finger_tip.dae"/>
        </geometry>
      </visual>
      <collision>
        <origin rpy="0 0 0" xyz="0 0 0"/>
        <geometry>
          <mesh filename="package://mobile_manipulator/mesh/barret/finger_tip.dae"/>
        </geometry>
        <contact_coefficients kd="1.0" kp="1000.0" mu="0"/>
      </collision>
    </link>

    <joint name="BH282__finger_32_to_finger_33_revolute_joint" type="revolute">
      <parent link="BH282_finger_32_link"/>
      <child link="BH282_finger_33_link"/>
      <origin rpy="0 0 0" xyz="-0.069936 0.003 0"/>
      <axis xyz="0 0 -1"/>
      <limit effort="30.0" lower="0.0" upper="0.84" velocity="2.0"/>
      <dynamics damping="100.0" friction="1.0"/>
    </joint>
    
  <!-- ###################################################### -->
  <!-- #################### Barrett Hand #################### -->

  <!-- ******************************** -->
  <!-- Barrett Hand connection to UR10 -->
    <joint name="BH282_base_to_end_effector_fixed_joint" type="fixed">
      <origin rpy="0.0 1.5707963267948966 0.0" xyz="0.0 0.0 0.0"/>
      <parent link="UR10_end_effector_link"/>
      <child link="BH282_base_link"/>
    </joint>
  <!-- Barrett Hand connection to UR10 -->
  <!-- ******************************** -->


</robot>
